2024-07-16 23:14:53,996 - wt_main.py[line:65] - INFO: 开始扫描事件文件夹：/Users/yanshigou/Downloads/15
2024-07-16 23:14:54,007 - wt_main.py[line:166] - ERROR: 【事件】程序出错：Traceback (most recent call last):
  File "wt_main.py", line 77, in event_run
  File "wt_file_manager.py", line 225, in scan_with_depth
  File "wt_file_manager.py", line 262, in __scan_with_depth
TypeError: '>=' not supported between instances of 'NoneType' and 'int'

2024-07-16 23:14:54,013 - wt_main.py[line:166] - ERROR: 【事件】程序出错：Traceback (most recent call last):
  File "wt_main.py", line 77, in event_run
  File "wt_file_manager.py", line 225, in scan_with_depth
  File "wt_file_manager.py", line 262, in __scan_with_depth
TypeError: '>=' not supported between instances of 'NoneType' and 'int'

2024-07-16 23:14:54,018 - wt_main.py[line:166] - ERROR: 【事件】程序出错：Traceback (most recent call last):
  File "wt_main.py", line 77, in event_run
  File "wt_file_manager.py", line 225, in scan_with_depth
  File "wt_file_manager.py", line 262, in __scan_with_depth
TypeError: '>=' not supported between instances of 'NoneType' and 'int'

2024-07-16 23:14:54,025 - wt_main.py[line:166] - ERROR: 【事件】程序出错：Traceback (most recent call last):
  File "wt_main.py", line 77, in event_run
  File "wt_file_manager.py", line 225, in scan_with_depth
  File "wt_file_manager.py", line 262, in __scan_with_depth
TypeError: '>=' not supported between instances of 'NoneType' and 'int'

2024-07-16 23:14:54,030 - wt_main.py[line:166] - ERROR: 【事件】程序出错：Traceback (most recent call last):
  File "wt_main.py", line 77, in event_run
  File "wt_file_manager.py", line 225, in scan_with_depth
  File "wt_file_manager.py", line 262, in __scan_with_depth
TypeError: '>=' not supported between instances of 'NoneType' and 'int'

2024-07-16 23:14:54,037 - wt_main.py[line:166] - ERROR: 【事件】程序出错：Traceback (most recent call last):
  File "wt_main.py", line 77, in event_run
  File "wt_file_manager.py", line 225, in scan_with_depth
  File "wt_file_manager.py", line 262, in __scan_with_depth
TypeError: '>=' not supported between instances of 'NoneType' and 'int'

2024-07-16 23:14:54,044 - wt_main.py[line:166] - ERROR: 【事件】程序出错：Traceback (most recent call last):
  File "wt_main.py", line 77, in event_run
  File "wt_file_manager.py", line 225, in scan_with_depth
  File "wt_file_manager.py", line 262, in __scan_with_depth
TypeError: '>=' not supported between instances of 'NoneType' and 'int'

2024-07-16 23:14:54,077 - wt_main.py[line:166] - ERROR: 【事件】程序出错：Traceback (most recent call last):
  File "wt_main.py", line 77, in event_run
  File "wt_file_manager.py", line 225, in scan_with_depth
  File "wt_file_manager.py", line 262, in __scan_with_depth
TypeError: '>=' not supported between instances of 'NoneType' and 'int'

2024-07-16 23:14:54,113 - wt_main.py[line:166] - ERROR: 【事件】程序出错：Traceback (most recent call last):
  File "wt_main.py", line 77, in event_run
  File "wt_file_manager.py", line 225, in scan_with_depth
  File "wt_file_manager.py", line 262, in __scan_with_depth
TypeError: '>=' not supported between instances of 'NoneType' and 'int'

2024-07-16 23:14:54,150 - wt_main.py[line:166] - ERROR: 【事件】程序出错：Traceback (most recent call last):
  File "wt_main.py", line 77, in event_run
  File "wt_file_manager.py", line 225, in scan_with_depth
  File "wt_file_manager.py", line 262, in __scan_with_depth
TypeError: '>=' not supported between instances of 'NoneType' and 'int'

2024-07-16 23:14:54,186 - wt_main.py[line:166] - ERROR: 【事件】程序出错：Traceback (most recent call last):
  File "wt_main.py", line 77, in event_run
  File "wt_file_manager.py", line 225, in scan_with_depth
  File "wt_file_manager.py", line 262, in __scan_with_depth
TypeError: '>=' not supported between instances of 'NoneType' and 'int'

2024-07-16 23:14:54,222 - wt_main.py[line:166] - ERROR: 【事件】程序出错：Traceback (most recent call last):
  File "wt_main.py", line 77, in event_run
  File "wt_file_manager.py", line 225, in scan_with_depth
  File "wt_file_manager.py", line 262, in __scan_with_depth
TypeError: '>=' not supported between instances of 'NoneType' and 'int'

2024-07-16 23:14:54,290 - wt_main.py[line:166] - ERROR: 【事件】程序出错：Traceback (most recent call last):
  File "wt_main.py", line 77, in event_run
  File "wt_file_manager.py", line 225, in scan_with_depth
  File "wt_file_manager.py", line 262, in __scan_with_depth
TypeError: '>=' not supported between instances of 'NoneType' and 'int'

2024-07-16 23:14:54,358 - wt_main.py[line:166] - ERROR: 【事件】程序出错：Traceback (most recent call last):
  File "wt_main.py", line 77, in event_run
  File "wt_file_manager.py", line 225, in scan_with_depth
  File "wt_file_manager.py", line 262, in __scan_with_depth
TypeError: '>=' not supported between instances of 'NoneType' and 'int'

2024-07-16 23:14:54,425 - wt_main.py[line:166] - ERROR: 【事件】程序出错：Traceback (most recent call last):
  File "wt_main.py", line 77, in event_run
  File "wt_file_manager.py", line 225, in scan_with_depth
  File "wt_file_manager.py", line 262, in __scan_with_depth
TypeError: '>=' not supported between instances of 'NoneType' and 'int'

2024-07-16 23:14:54,492 - wt_main.py[line:166] - ERROR: 【事件】程序出错：Traceback (most recent call last):
  File "wt_main.py", line 77, in event_run
  File "wt_file_manager.py", line 225, in scan_with_depth
  File "wt_file_manager.py", line 262, in __scan_with_depth
TypeError: '>=' not supported between instances of 'NoneType' and 'int'

2024-07-16 23:14:54,560 - wt_main.py[line:166] - ERROR: 【事件】程序出错：Traceback (most recent call last):
  File "wt_main.py", line 77, in event_run
  File "wt_file_manager.py", line 225, in scan_with_depth
  File "wt_file_manager.py", line 262, in __scan_with_depth
TypeError: '>=' not supported between instances of 'NoneType' and 'int'

2024-07-16 23:14:54,627 - wt_main.py[line:166] - ERROR: 【事件】程序出错：Traceback (most recent call last):
  File "wt_main.py", line 77, in event_run
  File "wt_file_manager.py", line 225, in scan_with_depth
  File "wt_file_manager.py", line 262, in __scan_with_depth
TypeError: '>=' not supported between instances of 'NoneType' and 'int'

2024-07-16 23:14:54,694 - wt_main.py[line:166] - ERROR: 【事件】程序出错：Traceback (most recent call last):
  File "wt_main.py", line 77, in event_run
  File "wt_file_manager.py", line 225, in scan_with_depth
  File "wt_file_manager.py", line 262, in __scan_with_depth
TypeError: '>=' not supported between instances of 'NoneType' and 'int'

2024-07-16 23:14:54,761 - wt_main.py[line:166] - ERROR: 【事件】程序出错：Traceback (most recent call last):
  File "wt_main.py", line 77, in event_run
  File "wt_file_manager.py", line 225, in scan_with_depth
  File "wt_file_manager.py", line 262, in __scan_with_depth
TypeError: '>=' not supported between instances of 'NoneType' and 'int'

2024-07-16 23:14:54,828 - wt_main.py[line:166] - ERROR: 【事件】程序出错：Traceback (most recent call last):
  File "wt_main.py", line 77, in event_run
  File "wt_file_manager.py", line 225, in scan_with_depth
  File "wt_file_manager.py", line 262, in __scan_with_depth
TypeError: '>=' not supported between instances of 'NoneType' and 'int'

2024-07-16 23:14:54,897 - wt_main.py[line:166] - ERROR: 【事件】程序出错：Traceback (most recent call last):
  File "wt_main.py", line 77, in event_run
  File "wt_file_manager.py", line 225, in scan_with_depth
  File "wt_file_manager.py", line 262, in __scan_with_depth
TypeError: '>=' not supported between instances of 'NoneType' and 'int'

2024-07-16 23:14:54,964 - wt_main.py[line:166] - ERROR: 【事件】程序出错：Traceback (most recent call last):
  File "wt_main.py", line 77, in event_run
  File "wt_file_manager.py", line 225, in scan_with_depth
  File "wt_file_manager.py", line 262, in __scan_with_depth
TypeError: '>=' not supported between instances of 'NoneType' and 'int'

2024-07-16 23:14:55,032 - wt_main.py[line:166] - ERROR: 【事件】程序出错：Traceback (most recent call last):
  File "wt_main.py", line 77, in event_run
  File "wt_file_manager.py", line 225, in scan_with_depth
  File "wt_file_manager.py", line 262, in __scan_with_depth
TypeError: '>=' not supported between instances of 'NoneType' and 'int'

2024-07-16 23:14:55,102 - wt_main.py[line:166] - ERROR: 【事件】程序出错：Traceback (most recent call last):
  File "wt_main.py", line 77, in event_run
  File "wt_file_manager.py", line 225, in scan_with_depth
  File "wt_file_manager.py", line 262, in __scan_with_depth
TypeError: '>=' not supported between instances of 'NoneType' and 'int'

2024-07-16 23:14:55,171 - wt_main.py[line:166] - ERROR: 【事件】程序出错：Traceback (most recent call last):
  File "wt_main.py", line 77, in event_run
  File "wt_file_manager.py", line 225, in scan_with_depth
  File "wt_file_manager.py", line 262, in __scan_with_depth
TypeError: '>=' not supported between instances of 'NoneType' and 'int'

2024-07-16 23:14:55,239 - wt_main.py[line:166] - ERROR: 【事件】程序出错：Traceback (most recent call last):
  File "wt_main.py", line 77, in event_run
  File "wt_file_manager.py", line 225, in scan_with_depth
  File "wt_file_manager.py", line 262, in __scan_with_depth
TypeError: '>=' not supported between instances of 'NoneType' and 'int'

2024-07-16 23:14:55,311 - wt_main.py[line:166] - ERROR: 【事件】程序出错：Traceback (most recent call last):
  File "wt_main.py", line 77, in event_run
  File "wt_file_manager.py", line 225, in scan_with_depth
  File "wt_file_manager.py", line 262, in __scan_with_depth
TypeError: '>=' not supported between instances of 'NoneType' and 'int'

2024-07-16 23:14:55,377 - wt_main.py[line:166] - ERROR: 【事件】程序出错：Traceback (most recent call last):
  File "wt_main.py", line 77, in event_run
  File "wt_file_manager.py", line 225, in scan_with_depth
  File "wt_file_manager.py", line 262, in __scan_with_depth
TypeError: '>=' not supported between instances of 'NoneType' and 'int'

2024-07-16 23:14:55,445 - wt_main.py[line:166] - ERROR: 【事件】程序出错：Traceback (most recent call last):
  File "wt_main.py", line 77, in event_run
  File "wt_file_manager.py", line 225, in scan_with_depth
  File "wt_file_manager.py", line 262, in __scan_with_depth
TypeError: '>=' not supported between instances of 'NoneType' and 'int'

2024-07-16 23:14:55,513 - wt_main.py[line:166] - ERROR: 【事件】程序出错：Traceback (most recent call last):
  File "wt_main.py", line 77, in event_run
  File "wt_file_manager.py", line 225, in scan_with_depth
  File "wt_file_manager.py", line 262, in __scan_with_depth
TypeError: '>=' not supported between instances of 'NoneType' and 'int'

2024-07-16 23:14:55,582 - wt_main.py[line:166] - ERROR: 【事件】程序出错：Traceback (most recent call last):
  File "wt_main.py", line 77, in event_run
  File "wt_file_manager.py", line 225, in scan_with_depth
  File "wt_file_manager.py", line 262, in __scan_with_depth
TypeError: '>=' not supported between instances of 'NoneType' and 'int'

2024-07-16 23:14:55,650 - wt_main.py[line:166] - ERROR: 【事件】程序出错：Traceback (most recent call last):
  File "wt_main.py", line 77, in event_run
  File "wt_file_manager.py", line 225, in scan_with_depth
  File "wt_file_manager.py", line 262, in __scan_with_depth
TypeError: '>=' not supported between instances of 'NoneType' and 'int'

2024-07-16 23:14:55,717 - wt_main.py[line:166] - ERROR: 【事件】程序出错：Traceback (most recent call last):
  File "wt_main.py", line 77, in event_run
  File "wt_file_manager.py", line 225, in scan_with_depth
  File "wt_file_manager.py", line 262, in __scan_with_depth
TypeError: '>=' not supported between instances of 'NoneType' and 'int'

2024-07-16 23:14:55,784 - wt_main.py[line:166] - ERROR: 【事件】程序出错：Traceback (most recent call last):
  File "wt_main.py", line 77, in event_run
  File "wt_file_manager.py", line 225, in scan_with_depth
  File "wt_file_manager.py", line 262, in __scan_with_depth
TypeError: '>=' not supported between instances of 'NoneType' and 'int'

2024-07-16 23:14:55,853 - wt_main.py[line:166] - ERROR: 【事件】程序出错：Traceback (most recent call last):
  File "wt_main.py", line 77, in event_run
  File "wt_file_manager.py", line 225, in scan_with_depth
  File "wt_file_manager.py", line 262, in __scan_with_depth
TypeError: '>=' not supported between instances of 'NoneType' and 'int'

2024-07-16 23:14:55,920 - wt_main.py[line:166] - ERROR: 【事件】程序出错：Traceback (most recent call last):
  File "wt_main.py", line 77, in event_run
  File "wt_file_manager.py", line 225, in scan_with_depth
  File "wt_file_manager.py", line 262, in __scan_with_depth
TypeError: '>=' not supported between instances of 'NoneType' and 'int'

2024-07-16 23:14:55,989 - wt_main.py[line:166] - ERROR: 【事件】程序出错：Traceback (most recent call last):
  File "wt_main.py", line 77, in event_run
  File "wt_file_manager.py", line 225, in scan_with_depth
  File "wt_file_manager.py", line 262, in __scan_with_depth
TypeError: '>=' not supported between instances of 'NoneType' and 'int'

2024-07-16 23:14:56,056 - wt_main.py[line:166] - ERROR: 【事件】程序出错：Traceback (most recent call last):
  File "wt_main.py", line 77, in event_run
  File "wt_file_manager.py", line 225, in scan_with_depth
  File "wt_file_manager.py", line 262, in __scan_with_depth
TypeError: '>=' not supported between instances of 'NoneType' and 'int'

2024-07-16 23:14:56,122 - wt_main.py[line:166] - ERROR: 【事件】程序出错：Traceback (most recent call last):
  File "wt_main.py", line 77, in event_run
  File "wt_file_manager.py", line 225, in scan_with_depth
  File "wt_file_manager.py", line 262, in __scan_with_depth
TypeError: '>=' not supported between instances of 'NoneType' and 'int'

2024-07-16 23:14:56,188 - wt_main.py[line:166] - ERROR: 【事件】程序出错：Traceback (most recent call last):
  File "wt_main.py", line 77, in event_run
  File "wt_file_manager.py", line 225, in scan_with_depth
  File "wt_file_manager.py", line 262, in __scan_with_depth
TypeError: '>=' not supported between instances of 'NoneType' and 'int'

2024-07-16 23:14:56,261 - wt_main.py[line:166] - ERROR: 【事件】程序出错：Traceback (most recent call last):
  File "wt_main.py", line 77, in event_run
  File "wt_file_manager.py", line 225, in scan_with_depth
  File "wt_file_manager.py", line 262, in __scan_with_depth
TypeError: '>=' not supported between instances of 'NoneType' and 'int'

2024-07-16 23:14:56,328 - wt_main.py[line:166] - ERROR: 【事件】程序出错：Traceback (most recent call last):
  File "wt_main.py", line 77, in event_run
  File "wt_file_manager.py", line 225, in scan_with_depth
  File "wt_file_manager.py", line 262, in __scan_with_depth
TypeError: '>=' not supported between instances of 'NoneType' and 'int'

2024-07-16 23:14:56,396 - wt_main.py[line:166] - ERROR: 【事件】程序出错：Traceback (most recent call last):
  File "wt_main.py", line 77, in event_run
  File "wt_file_manager.py", line 225, in scan_with_depth
  File "wt_file_manager.py", line 262, in __scan_with_depth
TypeError: '>=' not supported between instances of 'NoneType' and 'int'

2024-07-16 23:14:56,464 - wt_main.py[line:166] - ERROR: 【事件】程序出错：Traceback (most recent call last):
  File "wt_main.py", line 77, in event_run
  File "wt_file_manager.py", line 225, in scan_with_depth
  File "wt_file_manager.py", line 262, in __scan_with_depth
TypeError: '>=' not supported between instances of 'NoneType' and 'int'

2024-07-16 23:14:56,532 - wt_main.py[line:166] - ERROR: 【事件】程序出错：Traceback (most recent call last):
  File "wt_main.py", line 77, in event_run
  File "wt_file_manager.py", line 225, in scan_with_depth
  File "wt_file_manager.py", line 262, in __scan_with_depth
TypeError: '>=' not supported between instances of 'NoneType' and 'int'

2024-07-16 23:14:56,598 - wt_main.py[line:166] - ERROR: 【事件】程序出错：Traceback (most recent call last):
  File "wt_main.py", line 77, in event_run
  File "wt_file_manager.py", line 225, in scan_with_depth
  File "wt_file_manager.py", line 262, in __scan_with_depth
TypeError: '>=' not supported between instances of 'NoneType' and 'int'

2024-07-16 23:14:56,662 - wt_main.py[line:166] - ERROR: 【事件】程序出错：Traceback (most recent call last):
  File "wt_main.py", line 77, in event_run
  File "wt_file_manager.py", line 225, in scan_with_depth
  File "wt_file_manager.py", line 262, in __scan_with_depth
TypeError: '>=' not supported between instances of 'NoneType' and 'int'

2024-07-16 23:14:56,728 - wt_main.py[line:166] - ERROR: 【事件】程序出错：Traceback (most recent call last):
  File "wt_main.py", line 77, in event_run
  File "wt_file_manager.py", line 225, in scan_with_depth
  File "wt_file_manager.py", line 262, in __scan_with_depth
TypeError: '>=' not supported between instances of 'NoneType' and 'int'

2024-07-16 23:14:56,795 - wt_main.py[line:166] - ERROR: 【事件】程序出错：Traceback (most recent call last):
  File "wt_main.py", line 77, in event_run
  File "wt_file_manager.py", line 225, in scan_with_depth
  File "wt_file_manager.py", line 262, in __scan_with_depth
TypeError: '>=' not supported between instances of 'NoneType' and 'int'

2024-07-16 23:14:56,858 - wt_main.py[line:166] - ERROR: 【事件】程序出错：Traceback (most recent call last):
  File "wt_main.py", line 77, in event_run
  File "wt_file_manager.py", line 225, in scan_with_depth
  File "wt_file_manager.py", line 262, in __scan_with_depth
TypeError: '>=' not supported between instances of 'NoneType' and 'int'

2024-07-16 23:14:56,923 - wt_main.py[line:166] - ERROR: 【事件】程序出错：Traceback (most recent call last):
  File "wt_main.py", line 77, in event_run
  File "wt_file_manager.py", line 225, in scan_with_depth
  File "wt_file_manager.py", line 262, in __scan_with_depth
TypeError: '>=' not supported between instances of 'NoneType' and 'int'

2024-07-16 23:14:56,988 - wt_main.py[line:166] - ERROR: 【事件】程序出错：Traceback (most recent call last):
  File "wt_main.py", line 77, in event_run
  File "wt_file_manager.py", line 225, in scan_with_depth
  File "wt_file_manager.py", line 262, in __scan_with_depth
TypeError: '>=' not supported between instances of 'NoneType' and 'int'

2024-07-16 23:14:57,054 - wt_main.py[line:166] - ERROR: 【事件】程序出错：Traceback (most recent call last):
  File "wt_main.py", line 77, in event_run
  File "wt_file_manager.py", line 225, in scan_with_depth
  File "wt_file_manager.py", line 262, in __scan_with_depth
TypeError: '>=' not supported between instances of 'NoneType' and 'int'

2024-07-16 23:14:57,119 - wt_main.py[line:166] - ERROR: 【事件】程序出错：Traceback (most recent call last):
  File "wt_main.py", line 77, in event_run
  File "wt_file_manager.py", line 225, in scan_with_depth
  File "wt_file_manager.py", line 262, in __scan_with_depth
TypeError: '>=' not supported between instances of 'NoneType' and 'int'

2024-07-16 23:14:57,186 - wt_main.py[line:166] - ERROR: 【事件】程序出错：Traceback (most recent call last):
  File "wt_main.py", line 77, in event_run
  File "wt_file_manager.py", line 225, in scan_with_depth
  File "wt_file_manager.py", line 262, in __scan_with_depth
TypeError: '>=' not supported between instances of 'NoneType' and 'int'

2024-07-16 23:14:57,252 - wt_main.py[line:166] - ERROR: 【事件】程序出错：Traceback (most recent call last):
  File "wt_main.py", line 77, in event_run
  File "wt_file_manager.py", line 225, in scan_with_depth
  File "wt_file_manager.py", line 262, in __scan_with_depth
TypeError: '>=' not supported between instances of 'NoneType' and 'int'

2024-07-16 23:14:57,318 - wt_main.py[line:166] - ERROR: 【事件】程序出错：Traceback (most recent call last):
  File "wt_main.py", line 77, in event_run
  File "wt_file_manager.py", line 225, in scan_with_depth
  File "wt_file_manager.py", line 262, in __scan_with_depth
TypeError: '>=' not supported between instances of 'NoneType' and 'int'

2024-07-16 23:14:57,384 - wt_main.py[line:166] - ERROR: 【事件】程序出错：Traceback (most recent call last):
  File "wt_main.py", line 77, in event_run
  File "wt_file_manager.py", line 225, in scan_with_depth
  File "wt_file_manager.py", line 262, in __scan_with_depth
TypeError: '>=' not supported between instances of 'NoneType' and 'int'

2024-07-16 23:14:57,450 - wt_main.py[line:166] - ERROR: 【事件】程序出错：Traceback (most recent call last):
  File "wt_main.py", line 77, in event_run
  File "wt_file_manager.py", line 225, in scan_with_depth
  File "wt_file_manager.py", line 262, in __scan_with_depth
TypeError: '>=' not supported between instances of 'NoneType' and 'int'

2024-07-16 23:14:57,523 - wt_main.py[line:166] - ERROR: 【事件】程序出错：Traceback (most recent call last):
  File "wt_main.py", line 77, in event_run
  File "wt_file_manager.py", line 225, in scan_with_depth
  File "wt_file_manager.py", line 262, in __scan_with_depth
TypeError: '>=' not supported between instances of 'NoneType' and 'int'

2024-07-16 23:14:57,593 - wt_main.py[line:166] - ERROR: 【事件】程序出错：Traceback (most recent call last):
  File "wt_main.py", line 77, in event_run
  File "wt_file_manager.py", line 225, in scan_with_depth
  File "wt_file_manager.py", line 262, in __scan_with_depth
TypeError: '>=' not supported between instances of 'NoneType' and 'int'

2024-07-16 23:14:57,668 - wt_main.py[line:166] - ERROR: 【事件】程序出错：Traceback (most recent call last):
  File "wt_main.py", line 77, in event_run
  File "wt_file_manager.py", line 225, in scan_with_depth
  File "wt_file_manager.py", line 262, in __scan_with_depth
TypeError: '>=' not supported between instances of 'NoneType' and 'int'

2024-07-16 23:14:57,745 - wt_main.py[line:166] - ERROR: 【事件】程序出错：Traceback (most recent call last):
  File "wt_main.py", line 77, in event_run
  File "wt_file_manager.py", line 225, in scan_with_depth
  File "wt_file_manager.py", line 262, in __scan_with_depth
TypeError: '>=' not supported between instances of 'NoneType' and 'int'

2024-07-16 23:14:57,822 - wt_main.py[line:166] - ERROR: 【事件】程序出错：Traceback (most recent call last):
  File "wt_main.py", line 77, in event_run
  File "wt_file_manager.py", line 225, in scan_with_depth
  File "wt_file_manager.py", line 262, in __scan_with_depth
TypeError: '>=' not supported between instances of 'NoneType' and 'int'

2024-07-16 23:14:57,896 - wt_main.py[line:166] - ERROR: 【事件】程序出错：Traceback (most recent call last):
  File "wt_main.py", line 77, in event_run
  File "wt_file_manager.py", line 225, in scan_with_depth
  File "wt_file_manager.py", line 262, in __scan_with_depth
TypeError: '>=' not supported between instances of 'NoneType' and 'int'

2024-07-16 23:14:57,963 - wt_main.py[line:166] - ERROR: 【事件】程序出错：Traceback (most recent call last):
  File "wt_main.py", line 77, in event_run
  File "wt_file_manager.py", line 225, in scan_with_depth
  File "wt_file_manager.py", line 262, in __scan_with_depth
TypeError: '>=' not supported between instances of 'NoneType' and 'int'

2024-07-16 23:14:58,026 - wt_main.py[line:166] - ERROR: 【事件】程序出错：Traceback (most recent call last):
  File "wt_main.py", line 77, in event_run
  File "wt_file_manager.py", line 225, in scan_with_depth
  File "wt_file_manager.py", line 262, in __scan_with_depth
TypeError: '>=' not supported between instances of 'NoneType' and 'int'

2024-07-16 23:14:58,092 - wt_main.py[line:166] - ERROR: 【事件】程序出错：Traceback (most recent call last):
  File "wt_main.py", line 77, in event_run
  File "wt_file_manager.py", line 225, in scan_with_depth
  File "wt_file_manager.py", line 262, in __scan_with_depth
TypeError: '>=' not supported between instances of 'NoneType' and 'int'

2024-07-16 23:14:58,157 - wt_main.py[line:166] - ERROR: 【事件】程序出错：Traceback (most recent call last):
  File "wt_main.py", line 77, in event_run
  File "wt_file_manager.py", line 225, in scan_with_depth
  File "wt_file_manager.py", line 262, in __scan_with_depth
TypeError: '>=' not supported between instances of 'NoneType' and 'int'

2024-07-16 23:14:58,223 - wt_main.py[line:166] - ERROR: 【事件】程序出错：Traceback (most recent call last):
  File "wt_main.py", line 77, in event_run
  File "wt_file_manager.py", line 225, in scan_with_depth
  File "wt_file_manager.py", line 262, in __scan_with_depth
TypeError: '>=' not supported between instances of 'NoneType' and 'int'

2024-07-16 23:14:58,286 - wt_main.py[line:166] - ERROR: 【事件】程序出错：Traceback (most recent call last):
  File "wt_main.py", line 77, in event_run
  File "wt_file_manager.py", line 225, in scan_with_depth
  File "wt_file_manager.py", line 262, in __scan_with_depth
TypeError: '>=' not supported between instances of 'NoneType' and 'int'

2024-07-16 23:14:58,352 - wt_main.py[line:166] - ERROR: 【事件】程序出错：Traceback (most recent call last):
  File "wt_main.py", line 77, in event_run
  File "wt_file_manager.py", line 225, in scan_with_depth
  File "wt_file_manager.py", line 262, in __scan_with_depth
TypeError: '>=' not supported between instances of 'NoneType' and 'int'

2024-07-16 23:14:58,417 - wt_main.py[line:166] - ERROR: 【事件】程序出错：Traceback (most recent call last):
  File "wt_main.py", line 77, in event_run
  File "wt_file_manager.py", line 225, in scan_with_depth
  File "wt_file_manager.py", line 262, in __scan_with_depth
TypeError: '>=' not supported between instances of 'NoneType' and 'int'

2024-07-16 23:14:58,482 - wt_main.py[line:166] - ERROR: 【事件】程序出错：Traceback (most recent call last):
  File "wt_main.py", line 77, in event_run
  File "wt_file_manager.py", line 225, in scan_with_depth
  File "wt_file_manager.py", line 262, in __scan_with_depth
TypeError: '>=' not supported between instances of 'NoneType' and 'int'

2024-07-16 23:14:58,546 - wt_main.py[line:166] - ERROR: 【事件】程序出错：Traceback (most recent call last):
  File "wt_main.py", line 77, in event_run
  File "wt_file_manager.py", line 225, in scan_with_depth
  File "wt_file_manager.py", line 262, in __scan_with_depth
TypeError: '>=' not supported between instances of 'NoneType' and 'int'

2024-07-16 23:14:58,613 - wt_main.py[line:166] - ERROR: 【事件】程序出错：Traceback (most recent call last):
  File "wt_main.py", line 77, in event_run
  File "wt_file_manager.py", line 225, in scan_with_depth
  File "wt_file_manager.py", line 262, in __scan_with_depth
TypeError: '>=' not supported between instances of 'NoneType' and 'int'

2024-07-16 23:14:58,678 - wt_main.py[line:166] - ERROR: 【事件】程序出错：Traceback (most recent call last):
  File "wt_main.py", line 77, in event_run
  File "wt_file_manager.py", line 225, in scan_with_depth
  File "wt_file_manager.py", line 262, in __scan_with_depth
TypeError: '>=' not supported between instances of 'NoneType' and 'int'

2024-07-16 23:14:58,748 - wt_main.py[line:166] - ERROR: 【事件】程序出错：Traceback (most recent call last):
  File "wt_main.py", line 77, in event_run
  File "wt_file_manager.py", line 225, in scan_with_depth
  File "wt_file_manager.py", line 262, in __scan_with_depth
TypeError: '>=' not supported between instances of 'NoneType' and 'int'

2024-07-16 23:14:58,811 - wt_main.py[line:166] - ERROR: 【事件】程序出错：Traceback (most recent call last):
  File "wt_main.py", line 77, in event_run
  File "wt_file_manager.py", line 225, in scan_with_depth
  File "wt_file_manager.py", line 262, in __scan_with_depth
TypeError: '>=' not supported between instances of 'NoneType' and 'int'

2024-07-16 23:15:24,298 - wt_main.py[line:65] - INFO: 开始扫描事件文件夹：D:\历史项目管理\AutoScanning交通扫描软件\AutoScanning\dist\新建文件夹
2024-07-16 23:15:24,300 - wt_main.py[line:151] - INFO: 【事件】【扫描到文件夹】 D:\历史项目管理\AutoScanning交通扫描软件\AutoScanning\dist\新建文件夹，【未发现任何图片，休息5秒】
2024-07-16 23:15:30,302 - wt_main.py[line:151] - INFO: 【事件】【扫描到文件夹】 D:\历史项目管理\AutoScanning交通扫描软件\AutoScanning\dist\新建文件夹，【未发现任何图片，休息5秒】
2024-07-16 23:15:36,305 - wt_main.py[line:151] - INFO: 【事件】【扫描到文件夹】 D:\历史项目管理\AutoScanning交通扫描软件\AutoScanning\dist\新建文件夹，【未发现任何图片，休息5秒】
2024-07-16 23:15:42,307 - wt_main.py[line:151] - INFO: 【事件】【扫描到文件夹】 D:\历史项目管理\AutoScanning交通扫描软件\AutoScanning\dist\新建文件夹，【未发现任何图片，休息5秒】
2024-07-16 23:15:48,309 - wt_main.py[line:151] - INFO: 【事件】【扫描到文件夹】 D:\历史项目管理\AutoScanning交通扫描软件\AutoScanning\dist\新建文件夹，【未发现任何图片，休息5秒】
2024-07-16 23:15:54,312 - wt_main.py[line:151] - INFO: 【事件】【扫描到文件夹】 D:\历史项目管理\AutoScanning交通扫描软件\AutoScanning\dist\新建文件夹，【未发现任何图片，休息5秒】
2024-07-16 23:16:00,315 - wt_main.py[line:151] - INFO: 【事件】【扫描到文件夹】 D:\历史项目管理\AutoScanning交通扫描软件\AutoScanning\dist\新建文件夹，【未发现任何图片，休息5秒】
2024-07-16 23:16:06,316 - wt_main.py[line:151] - INFO: 【事件】【扫描到文件夹】 D:\历史项目管理\AutoScanning交通扫描软件\AutoScanning\dist\新建文件夹，【未发现任何图片，休息5秒】
2024-07-16 23:16:12,319 - wt_main.py[line:151] - INFO: 【事件】【扫描到文件夹】 D:\历史项目管理\AutoScanning交通扫描软件\AutoScanning\dist\新建文件夹，【未发现任何图片，休息5秒】
2024-07-16 23:16:18,321 - wt_main.py[line:151] - INFO: 【事件】【扫描到文件夹】 D:\历史项目管理\AutoScanning交通扫描软件\AutoScanning\dist\新建文件夹，【未发现任何图片，休息5秒】
2024-07-16 23:17:35,293 - wt_main.py[line:65] - INFO: 开始扫描事件文件夹：D:\历史项目管理\AutoScanning交通扫描软件\AutoScanning\dist\新建文件夹
2024-07-16 23:17:35,295 - wt_main.py[line:151] - INFO: 【事件】【扫描到文件夹】 D:\历史项目管理\AutoScanning交通扫描软件\AutoScanning\dist\新建文件夹，【未发现任何图片，休息5秒】
2024-07-16 23:17:35,988 - wt_main.py[line:65] - INFO: 开始扫描事件文件夹：D:\历史项目管理\AutoScanning交通扫描软件\AutoScanning\dist\新建文件夹
2024-07-16 23:17:35,991 - wt_main.py[line:151] - INFO: 【事件】【扫描到文件夹】 D:\历史项目管理\AutoScanning交通扫描软件\AutoScanning\dist\新建文件夹，【未发现任何图片，休息5秒】
2024-07-16 23:17:37,196 - wt_main.py[line:65] - INFO: 开始扫描事件文件夹：D:\历史项目管理\AutoScanning交通扫描软件\AutoScanning\dist\新建文件夹
2024-07-16 23:17:37,199 - wt_main.py[line:151] - INFO: 【事件】【扫描到文件夹】 D:\历史项目管理\AutoScanning交通扫描软件\AutoScanning\dist\新建文件夹，【未发现任何图片，休息5秒】
2024-07-16 23:17:38,148 - wt_main.py[line:65] - INFO: 开始扫描事件文件夹：D:\历史项目管理\AutoScanning交通扫描软件\AutoScanning\dist\新建文件夹
2024-07-16 23:17:38,150 - wt_main.py[line:151] - INFO: 【事件】【扫描到文件夹】 D:\历史项目管理\AutoScanning交通扫描软件\AutoScanning\dist\新建文件夹，【未发现任何图片，休息5秒】
2024-07-16 23:17:38,420 - wt_main.py[line:65] - INFO: 开始扫描事件文件夹：D:\历史项目管理\AutoScanning交通扫描软件\AutoScanning\dist\新建文件夹
2024-07-16 23:17:38,422 - wt_main.py[line:151] - INFO: 【事件】【扫描到文件夹】 D:\历史项目管理\AutoScanning交通扫描软件\AutoScanning\dist\新建文件夹，【未发现任何图片，休息5秒】
2024-07-16 23:17:38,588 - wt_main.py[line:65] - INFO: 开始扫描事件文件夹：D:\历史项目管理\AutoScanning交通扫描软件\AutoScanning\dist\新建文件夹
2024-07-16 23:17:38,590 - wt_main.py[line:151] - INFO: 【事件】【扫描到文件夹】 D:\历史项目管理\AutoScanning交通扫描软件\AutoScanning\dist\新建文件夹，【未发现任何图片，休息5秒】
2024-07-16 23:17:38,747 - wt_main.py[line:65] - INFO: 开始扫描事件文件夹：D:\历史项目管理\AutoScanning交通扫描软件\AutoScanning\dist\新建文件夹
2024-07-16 23:17:38,749 - wt_main.py[line:151] - INFO: 【事件】【扫描到文件夹】 D:\历史项目管理\AutoScanning交通扫描软件\AutoScanning\dist\新建文件夹，【未发现任何图片，休息5秒】
2024-07-16 23:17:38,875 - wt_main.py[line:65] - INFO: 开始扫描事件文件夹：D:\历史项目管理\AutoScanning交通扫描软件\AutoScanning\dist\新建文件夹
2024-07-16 23:17:38,877 - wt_main.py[line:151] - INFO: 【事件】【扫描到文件夹】 D:\历史项目管理\AutoScanning交通扫描软件\AutoScanning\dist\新建文件夹，【未发现任何图片，休息5秒】
2024-07-16 23:17:39,012 - wt_main.py[line:65] - INFO: 开始扫描事件文件夹：D:\历史项目管理\AutoScanning交通扫描软件\AutoScanning\dist\新建文件夹
2024-07-16 23:17:39,014 - wt_main.py[line:151] - INFO: 【事件】【扫描到文件夹】 D:\历史项目管理\AutoScanning交通扫描软件\AutoScanning\dist\新建文件夹，【未发现任何图片，休息5秒】
2024-07-16 23:17:39,150 - wt_main.py[line:65] - INFO: 开始扫描事件文件夹：D:\历史项目管理\AutoScanning交通扫描软件\AutoScanning\dist\新建文件夹
2024-07-16 23:17:39,152 - wt_main.py[line:151] - INFO: 【事件】【扫描到文件夹】 D:\历史项目管理\AutoScanning交通扫描软件\AutoScanning\dist\新建文件夹，【未发现任何图片，休息5秒】
2024-07-16 23:17:41,298 - wt_main.py[line:151] - INFO: 【事件】【扫描到文件夹】 D:\历史项目管理\AutoScanning交通扫描软件\AutoScanning\dist\新建文件夹，【未发现任何图片，休息5秒】
2024-07-16 23:17:41,994 - wt_main.py[line:151] - INFO: 【事件】【扫描到文件夹】 D:\历史项目管理\AutoScanning交通扫描软件\AutoScanning\dist\新建文件夹，【未发现任何图片，休息5秒】
2024-07-16 23:17:43,202 - wt_main.py[line:151] - INFO: 【事件】【扫描到文件夹】 D:\历史项目管理\AutoScanning交通扫描软件\AutoScanning\dist\新建文件夹，【未发现任何图片，休息5秒】
2024-07-16 23:17:44,153 - wt_main.py[line:151] - INFO: 【事件】【扫描到文件夹】 D:\历史项目管理\AutoScanning交通扫描软件\AutoScanning\dist\新建文件夹，【未发现任何图片，休息5秒】
2024-07-16 23:17:44,425 - wt_main.py[line:151] - INFO: 【事件】【扫描到文件夹】 D:\历史项目管理\AutoScanning交通扫描软件\AutoScanning\dist\新建文件夹，【未发现任何图片，休息5秒】
2024-07-16 23:17:44,593 - wt_main.py[line:151] - INFO: 【事件】【扫描到文件夹】 D:\历史项目管理\AutoScanning交通扫描软件\AutoScanning\dist\新建文件夹，【未发现任何图片，休息5秒】
2024-07-16 23:17:44,752 - wt_main.py[line:151] - INFO: 【事件】【扫描到文件夹】 D:\历史项目管理\AutoScanning交通扫描软件\AutoScanning\dist\新建文件夹，【未发现任何图片，休息5秒】
2024-07-16 23:17:44,880 - wt_main.py[line:151] - INFO: 【事件】【扫描到文件夹】 D:\历史项目管理\AutoScanning交通扫描软件\AutoScanning\dist\新建文件夹，【未发现任何图片，休息5秒】
2024-07-16 23:17:45,018 - wt_main.py[line:151] - INFO: 【事件】【扫描到文件夹】 D:\历史项目管理\AutoScanning交通扫描软件\AutoScanning\dist\新建文件夹，【未发现任何图片，休息5秒】
2024-07-16 23:17:45,155 - wt_main.py[line:151] - INFO: 【事件】【扫描到文件夹】 D:\历史项目管理\AutoScanning交通扫描软件\AutoScanning\dist\新建文件夹，【未发现任何图片，休息5秒】
2024-07-16 23:17:47,301 - wt_main.py[line:151] - INFO: 【事件】【扫描到文件夹】 D:\历史项目管理\AutoScanning交通扫描软件\AutoScanning\dist\新建文件夹，【未发现任何图片，休息5秒】
2024-07-16 23:17:47,997 - wt_main.py[line:151] - INFO: 【事件】【扫描到文件夹】 D:\历史项目管理\AutoScanning交通扫描软件\AutoScanning\dist\新建文件夹，【未发现任何图片，休息5秒】
2024-07-16 23:17:49,205 - wt_main.py[line:151] - INFO: 【事件】【扫描到文件夹】 D:\历史项目管理\AutoScanning交通扫描软件\AutoScanning\dist\新建文件夹，【未发现任何图片，休息5秒】
2024-07-16 23:17:50,156 - wt_main.py[line:151] - INFO: 【事件】【扫描到文件夹】 D:\历史项目管理\AutoScanning交通扫描软件\AutoScanning\dist\新建文件夹，【未发现任何图片，休息5秒】
2024-07-16 23:17:50,427 - wt_main.py[line:151] - INFO: 【事件】【扫描到文件夹】 D:\历史项目管理\AutoScanning交通扫描软件\AutoScanning\dist\新建文件夹，【未发现任何图片，休息5秒】
2024-07-16 23:17:50,596 - wt_main.py[line:151] - INFO: 【事件】【扫描到文件夹】 D:\历史项目管理\AutoScanning交通扫描软件\AutoScanning\dist\新建文件夹，【未发现任何图片，休息5秒】
2024-07-16 23:17:50,754 - wt_main.py[line:151] - INFO: 【事件】【扫描到文件夹】 D:\历史项目管理\AutoScanning交通扫描软件\AutoScanning\dist\新建文件夹，【未发现任何图片，休息5秒】
2024-07-16 23:17:50,883 - wt_main.py[line:151] - INFO: 【事件】【扫描到文件夹】 D:\历史项目管理\AutoScanning交通扫描软件\AutoScanning\dist\新建文件夹，【未发现任何图片，休息5秒】
2024-07-16 23:17:51,021 - wt_main.py[line:151] - INFO: 【事件】【扫描到文件夹】 D:\历史项目管理\AutoScanning交通扫描软件\AutoScanning\dist\新建文件夹，【未发现任何图片，休息5秒】
2024-07-16 23:17:51,158 - wt_main.py[line:151] - INFO: 【事件】【扫描到文件夹】 D:\历史项目管理\AutoScanning交通扫描软件\AutoScanning\dist\新建文件夹，【未发现任何图片，休息5秒】
2024-07-16 23:17:53,303 - wt_main.py[line:151] - INFO: 【事件】【扫描到文件夹】 D:\历史项目管理\AutoScanning交通扫描软件\AutoScanning\dist\新建文件夹，【未发现任何图片，休息5秒】
2024-07-16 23:17:53,999 - wt_main.py[line:151] - INFO: 【事件】【扫描到文件夹】 D:\历史项目管理\AutoScanning交通扫描软件\AutoScanning\dist\新建文件夹，【未发现任何图片，休息5秒】
2024-07-16 23:17:55,207 - wt_main.py[line:151] - INFO: 【事件】【扫描到文件夹】 D:\历史项目管理\AutoScanning交通扫描软件\AutoScanning\dist\新建文件夹，【未发现任何图片，休息5秒】
2024-07-16 23:17:56,158 - wt_main.py[line:151] - INFO: 【事件】【扫描到文件夹】 D:\历史项目管理\AutoScanning交通扫描软件\AutoScanning\dist\新建文件夹，【未发现任何图片，休息5秒】
2024-07-16 23:17:56,429 - wt_main.py[line:151] - INFO: 【事件】【扫描到文件夹】 D:\历史项目管理\AutoScanning交通扫描软件\AutoScanning\dist\新建文件夹，【未发现任何图片，休息5秒】
2024-07-16 23:17:56,598 - wt_main.py[line:151] - INFO: 【事件】【扫描到文件夹】 D:\历史项目管理\AutoScanning交通扫描软件\AutoScanning\dist\新建文件夹，【未发现任何图片，休息5秒】
2024-07-16 23:17:56,756 - wt_main.py[line:151] - INFO: 【事件】【扫描到文件夹】 D:\历史项目管理\AutoScanning交通扫描软件\AutoScanning\dist\新建文件夹，【未发现任何图片，休息5秒】
2024-07-16 23:17:56,886 - wt_main.py[line:151] - INFO: 【事件】【扫描到文件夹】 D:\历史项目管理\AutoScanning交通扫描软件\AutoScanning\dist\新建文件夹，【未发现任何图片，休息5秒】
2024-07-16 23:17:57,023 - wt_main.py[line:151] - INFO: 【事件】【扫描到文件夹】 D:\历史项目管理\AutoScanning交通扫描软件\AutoScanning\dist\新建文件夹，【未发现任何图片，休息5秒】
2024-07-16 23:17:57,161 - wt_main.py[line:151] - INFO: 【事件】【扫描到文件夹】 D:\历史项目管理\AutoScanning交通扫描软件\AutoScanning\dist\新建文件夹，【未发现任何图片，休息5秒】
2024-07-16 23:17:59,305 - wt_main.py[line:151] - INFO: 【事件】【扫描到文件夹】 D:\历史项目管理\AutoScanning交通扫描软件\AutoScanning\dist\新建文件夹，【未发现任何图片，休息5秒】
2024-07-16 23:18:00,002 - wt_main.py[line:151] - INFO: 【事件】【扫描到文件夹】 D:\历史项目管理\AutoScanning交通扫描软件\AutoScanning\dist\新建文件夹，【未发现任何图片，休息5秒】
2024-07-16 23:18:01,208 - wt_main.py[line:151] - INFO: 【事件】【扫描到文件夹】 D:\历史项目管理\AutoScanning交通扫描软件\AutoScanning\dist\新建文件夹，【未发现任何图片，休息5秒】
2024-07-16 23:18:02,161 - wt_main.py[line:151] - INFO: 【事件】【扫描到文件夹】 D:\历史项目管理\AutoScanning交通扫描软件\AutoScanning\dist\新建文件夹，【未发现任何图片，休息5秒】
2024-07-16 23:18:02,432 - wt_main.py[line:151] - INFO: 【事件】【扫描到文件夹】 D:\历史项目管理\AutoScanning交通扫描软件\AutoScanning\dist\新建文件夹，【未发现任何图片，休息5秒】
2024-07-16 23:18:02,600 - wt_main.py[line:151] - INFO: 【事件】【扫描到文件夹】 D:\历史项目管理\AutoScanning交通扫描软件\AutoScanning\dist\新建文件夹，【未发现任何图片，休息5秒】
2024-07-16 23:18:02,760 - wt_main.py[line:151] - INFO: 【事件】【扫描到文件夹】 D:\历史项目管理\AutoScanning交通扫描软件\AutoScanning\dist\新建文件夹，【未发现任何图片，休息5秒】
2024-07-16 23:18:02,888 - wt_main.py[line:151] - INFO: 【事件】【扫描到文件夹】 D:\历史项目管理\AutoScanning交通扫描软件\AutoScanning\dist\新建文件夹，【未发现任何图片，休息5秒】
2024-07-16 23:18:03,025 - wt_main.py[line:151] - INFO: 【事件】【扫描到文件夹】 D:\历史项目管理\AutoScanning交通扫描软件\AutoScanning\dist\新建文件夹，【未发现任何图片，休息5秒】
2024-07-16 23:18:03,163 - wt_main.py[line:151] - INFO: 【事件】【扫描到文件夹】 D:\历史项目管理\AutoScanning交通扫描软件\AutoScanning\dist\新建文件夹，【未发现任何图片，休息5秒】
2024-07-16 23:18:05,308 - wt_main.py[line:151] - INFO: 【事件】【扫描到文件夹】 D:\历史项目管理\AutoScanning交通扫描软件\AutoScanning\dist\新建文件夹，【未发现任何图片，休息5秒】
2024-07-16 23:40:23,043 - wt_main.py[line:67] - INFO: 开始扫描事件文件夹：D:\历史项目管理\AutoScanning交通扫描软件\AutoScanning\dist\新建文件夹
2024-07-16 23:40:23,045 - wt_main.py[line:153] - INFO: 【事件】【扫描到文件夹】 D:\历史项目管理\AutoScanning交通扫描软件\AutoScanning\dist\新建文件夹，【未发现任何图片，休息5秒】
2024-07-16 23:40:24,043 - wt_main.py[line:67] - INFO: 开始扫描事件文件夹：D:\历史项目管理\AutoScanning交通扫描软件\AutoScanning\dist\新建文件夹
2024-07-16 23:40:24,045 - wt_main.py[line:153] - INFO: 【事件】【扫描到文件夹】 D:\历史项目管理\AutoScanning交通扫描软件\AutoScanning\dist\新建文件夹，【未发现任何图片，休息5秒】
