2024-07-16 23:14:53,996 - wt_main.py[line:179] - INFO: 开始扫描取证文件夹：/Users/yanshigou/Downloads/16
2024-07-16 23:14:54,007 - wt_main.py[line:247] - ERROR: 【取证】程序出错：Traceback (most recent call last):
  File "wt_main.py", line 191, in QZ_run
  File "wt_file_manager.py", line 225, in scan_with_depth
  File "wt_file_manager.py", line 262, in __scan_with_depth
TypeError: '>=' not supported between instances of 'NoneType' and 'int'

2024-07-16 23:14:54,013 - wt_main.py[line:247] - ERROR: 【取证】程序出错：Traceback (most recent call last):
  File "wt_main.py", line 191, in QZ_run
  File "wt_file_manager.py", line 225, in scan_with_depth
  File "wt_file_manager.py", line 262, in __scan_with_depth
TypeError: '>=' not supported between instances of 'NoneType' and 'int'

2024-07-16 23:14:54,018 - wt_main.py[line:247] - ERROR: 【取证】程序出错：Traceback (most recent call last):
  File "wt_main.py", line 191, in QZ_run
  File "wt_file_manager.py", line 225, in scan_with_depth
  File "wt_file_manager.py", line 262, in __scan_with_depth
TypeError: '>=' not supported between instances of 'NoneType' and 'int'

2024-07-16 23:14:54,025 - wt_main.py[line:247] - ERROR: 【取证】程序出错：Traceback (most recent call last):
  File "wt_main.py", line 191, in QZ_run
  File "wt_file_manager.py", line 225, in scan_with_depth
  File "wt_file_manager.py", line 262, in __scan_with_depth
TypeError: '>=' not supported between instances of 'NoneType' and 'int'

2024-07-16 23:14:54,030 - wt_main.py[line:247] - ERROR: 【取证】程序出错：Traceback (most recent call last):
  File "wt_main.py", line 191, in QZ_run
  File "wt_file_manager.py", line 225, in scan_with_depth
  File "wt_file_manager.py", line 262, in __scan_with_depth
TypeError: '>=' not supported between instances of 'NoneType' and 'int'

2024-07-16 23:14:54,037 - wt_main.py[line:247] - ERROR: 【取证】程序出错：Traceback (most recent call last):
  File "wt_main.py", line 191, in QZ_run
  File "wt_file_manager.py", line 225, in scan_with_depth
  File "wt_file_manager.py", line 262, in __scan_with_depth
TypeError: '>=' not supported between instances of 'NoneType' and 'int'

2024-07-16 23:14:54,044 - wt_main.py[line:247] - ERROR: 【取证】程序出错：Traceback (most recent call last):
  File "wt_main.py", line 191, in QZ_run
  File "wt_file_manager.py", line 225, in scan_with_depth
  File "wt_file_manager.py", line 262, in __scan_with_depth
TypeError: '>=' not supported between instances of 'NoneType' and 'int'

2024-07-16 23:14:54,078 - wt_main.py[line:247] - ERROR: 【取证】程序出错：Traceback (most recent call last):
  File "wt_main.py", line 191, in QZ_run
  File "wt_file_manager.py", line 225, in scan_with_depth
  File "wt_file_manager.py", line 262, in __scan_with_depth
TypeError: '>=' not supported between instances of 'NoneType' and 'int'

2024-07-16 23:14:54,113 - wt_main.py[line:247] - ERROR: 【取证】程序出错：Traceback (most recent call last):
  File "wt_main.py", line 191, in QZ_run
  File "wt_file_manager.py", line 225, in scan_with_depth
  File "wt_file_manager.py", line 262, in __scan_with_depth
TypeError: '>=' not supported between instances of 'NoneType' and 'int'

2024-07-16 23:14:54,150 - wt_main.py[line:247] - ERROR: 【取证】程序出错：Traceback (most recent call last):
  File "wt_main.py", line 191, in QZ_run
  File "wt_file_manager.py", line 225, in scan_with_depth
  File "wt_file_manager.py", line 262, in __scan_with_depth
TypeError: '>=' not supported between instances of 'NoneType' and 'int'

2024-07-16 23:14:54,186 - wt_main.py[line:247] - ERROR: 【取证】程序出错：Traceback (most recent call last):
  File "wt_main.py", line 191, in QZ_run
  File "wt_file_manager.py", line 225, in scan_with_depth
  File "wt_file_manager.py", line 262, in __scan_with_depth
TypeError: '>=' not supported between instances of 'NoneType' and 'int'

2024-07-16 23:14:54,256 - wt_main.py[line:247] - ERROR: 【取证】程序出错：Traceback (most recent call last):
  File "wt_main.py", line 191, in QZ_run
  File "wt_file_manager.py", line 225, in scan_with_depth
  File "wt_file_manager.py", line 262, in __scan_with_depth
TypeError: '>=' not supported between instances of 'NoneType' and 'int'

2024-07-16 23:14:54,323 - wt_main.py[line:247] - ERROR: 【取证】程序出错：Traceback (most recent call last):
  File "wt_main.py", line 191, in QZ_run
  File "wt_file_manager.py", line 225, in scan_with_depth
  File "wt_file_manager.py", line 262, in __scan_with_depth
TypeError: '>=' not supported between instances of 'NoneType' and 'int'

2024-07-16 23:14:54,391 - wt_main.py[line:247] - ERROR: 【取证】程序出错：Traceback (most recent call last):
  File "wt_main.py", line 191, in QZ_run
  File "wt_file_manager.py", line 225, in scan_with_depth
  File "wt_file_manager.py", line 262, in __scan_with_depth
TypeError: '>=' not supported between instances of 'NoneType' and 'int'

2024-07-16 23:14:54,459 - wt_main.py[line:247] - ERROR: 【取证】程序出错：Traceback (most recent call last):
  File "wt_main.py", line 191, in QZ_run
  File "wt_file_manager.py", line 225, in scan_with_depth
  File "wt_file_manager.py", line 262, in __scan_with_depth
TypeError: '>=' not supported between instances of 'NoneType' and 'int'

2024-07-16 23:14:54,527 - wt_main.py[line:247] - ERROR: 【取证】程序出错：Traceback (most recent call last):
  File "wt_main.py", line 191, in QZ_run
  File "wt_file_manager.py", line 225, in scan_with_depth
  File "wt_file_manager.py", line 262, in __scan_with_depth
TypeError: '>=' not supported between instances of 'NoneType' and 'int'

2024-07-16 23:14:54,593 - wt_main.py[line:247] - ERROR: 【取证】程序出错：Traceback (most recent call last):
  File "wt_main.py", line 191, in QZ_run
  File "wt_file_manager.py", line 225, in scan_with_depth
  File "wt_file_manager.py", line 262, in __scan_with_depth
TypeError: '>=' not supported between instances of 'NoneType' and 'int'

2024-07-16 23:14:54,660 - wt_main.py[line:247] - ERROR: 【取证】程序出错：Traceback (most recent call last):
  File "wt_main.py", line 191, in QZ_run
  File "wt_file_manager.py", line 225, in scan_with_depth
  File "wt_file_manager.py", line 262, in __scan_with_depth
TypeError: '>=' not supported between instances of 'NoneType' and 'int'

2024-07-16 23:14:54,728 - wt_main.py[line:247] - ERROR: 【取证】程序出错：Traceback (most recent call last):
  File "wt_main.py", line 191, in QZ_run
  File "wt_file_manager.py", line 225, in scan_with_depth
  File "wt_file_manager.py", line 262, in __scan_with_depth
TypeError: '>=' not supported between instances of 'NoneType' and 'int'

2024-07-16 23:14:54,794 - wt_main.py[line:247] - ERROR: 【取证】程序出错：Traceback (most recent call last):
  File "wt_main.py", line 191, in QZ_run
  File "wt_file_manager.py", line 225, in scan_with_depth
  File "wt_file_manager.py", line 262, in __scan_with_depth
TypeError: '>=' not supported between instances of 'NoneType' and 'int'

2024-07-16 23:14:54,861 - wt_main.py[line:247] - ERROR: 【取证】程序出错：Traceback (most recent call last):
  File "wt_main.py", line 191, in QZ_run
  File "wt_file_manager.py", line 225, in scan_with_depth
  File "wt_file_manager.py", line 262, in __scan_with_depth
TypeError: '>=' not supported between instances of 'NoneType' and 'int'

2024-07-16 23:14:54,931 - wt_main.py[line:247] - ERROR: 【取证】程序出错：Traceback (most recent call last):
  File "wt_main.py", line 191, in QZ_run
  File "wt_file_manager.py", line 225, in scan_with_depth
  File "wt_file_manager.py", line 262, in __scan_with_depth
TypeError: '>=' not supported between instances of 'NoneType' and 'int'

2024-07-16 23:14:54,998 - wt_main.py[line:247] - ERROR: 【取证】程序出错：Traceback (most recent call last):
  File "wt_main.py", line 191, in QZ_run
  File "wt_file_manager.py", line 225, in scan_with_depth
  File "wt_file_manager.py", line 262, in __scan_with_depth
TypeError: '>=' not supported between instances of 'NoneType' and 'int'

2024-07-16 23:14:55,067 - wt_main.py[line:247] - ERROR: 【取证】程序出错：Traceback (most recent call last):
  File "wt_main.py", line 191, in QZ_run
  File "wt_file_manager.py", line 225, in scan_with_depth
  File "wt_file_manager.py", line 262, in __scan_with_depth
TypeError: '>=' not supported between instances of 'NoneType' and 'int'

2024-07-16 23:14:55,135 - wt_main.py[line:247] - ERROR: 【取证】程序出错：Traceback (most recent call last):
  File "wt_main.py", line 191, in QZ_run
  File "wt_file_manager.py", line 225, in scan_with_depth
  File "wt_file_manager.py", line 262, in __scan_with_depth
TypeError: '>=' not supported between instances of 'NoneType' and 'int'

2024-07-16 23:14:55,205 - wt_main.py[line:247] - ERROR: 【取证】程序出错：Traceback (most recent call last):
  File "wt_main.py", line 191, in QZ_run
  File "wt_file_manager.py", line 225, in scan_with_depth
  File "wt_file_manager.py", line 262, in __scan_with_depth
TypeError: '>=' not supported between instances of 'NoneType' and 'int'

2024-07-16 23:14:55,277 - wt_main.py[line:247] - ERROR: 【取证】程序出错：Traceback (most recent call last):
  File "wt_main.py", line 191, in QZ_run
  File "wt_file_manager.py", line 225, in scan_with_depth
  File "wt_file_manager.py", line 262, in __scan_with_depth
TypeError: '>=' not supported between instances of 'NoneType' and 'int'

2024-07-16 23:14:55,344 - wt_main.py[line:247] - ERROR: 【取证】程序出错：Traceback (most recent call last):
  File "wt_main.py", line 191, in QZ_run
  File "wt_file_manager.py", line 225, in scan_with_depth
  File "wt_file_manager.py", line 262, in __scan_with_depth
TypeError: '>=' not supported between instances of 'NoneType' and 'int'

2024-07-16 23:14:55,411 - wt_main.py[line:247] - ERROR: 【取证】程序出错：Traceback (most recent call last):
  File "wt_main.py", line 191, in QZ_run
  File "wt_file_manager.py", line 225, in scan_with_depth
  File "wt_file_manager.py", line 262, in __scan_with_depth
TypeError: '>=' not supported between instances of 'NoneType' and 'int'

2024-07-16 23:14:55,479 - wt_main.py[line:247] - ERROR: 【取证】程序出错：Traceback (most recent call last):
  File "wt_main.py", line 191, in QZ_run
  File "wt_file_manager.py", line 225, in scan_with_depth
  File "wt_file_manager.py", line 262, in __scan_with_depth
TypeError: '>=' not supported between instances of 'NoneType' and 'int'

2024-07-16 23:14:55,546 - wt_main.py[line:247] - ERROR: 【取证】程序出错：Traceback (most recent call last):
  File "wt_main.py", line 191, in QZ_run
  File "wt_file_manager.py", line 225, in scan_with_depth
  File "wt_file_manager.py", line 262, in __scan_with_depth
TypeError: '>=' not supported between instances of 'NoneType' and 'int'

2024-07-16 23:14:55,616 - wt_main.py[line:247] - ERROR: 【取证】程序出错：Traceback (most recent call last):
  File "wt_main.py", line 191, in QZ_run
  File "wt_file_manager.py", line 225, in scan_with_depth
  File "wt_file_manager.py", line 262, in __scan_with_depth
TypeError: '>=' not supported between instances of 'NoneType' and 'int'

2024-07-16 23:14:55,683 - wt_main.py[line:247] - ERROR: 【取证】程序出错：Traceback (most recent call last):
  File "wt_main.py", line 191, in QZ_run
  File "wt_file_manager.py", line 225, in scan_with_depth
  File "wt_file_manager.py", line 262, in __scan_with_depth
TypeError: '>=' not supported between instances of 'NoneType' and 'int'

2024-07-16 23:14:55,751 - wt_main.py[line:247] - ERROR: 【取证】程序出错：Traceback (most recent call last):
  File "wt_main.py", line 191, in QZ_run
  File "wt_file_manager.py", line 225, in scan_with_depth
  File "wt_file_manager.py", line 262, in __scan_with_depth
TypeError: '>=' not supported between instances of 'NoneType' and 'int'

2024-07-16 23:14:55,819 - wt_main.py[line:247] - ERROR: 【取证】程序出错：Traceback (most recent call last):
  File "wt_main.py", line 191, in QZ_run
  File "wt_file_manager.py", line 225, in scan_with_depth
  File "wt_file_manager.py", line 262, in __scan_with_depth
TypeError: '>=' not supported between instances of 'NoneType' and 'int'

2024-07-16 23:14:55,886 - wt_main.py[line:247] - ERROR: 【取证】程序出错：Traceback (most recent call last):
  File "wt_main.py", line 191, in QZ_run
  File "wt_file_manager.py", line 225, in scan_with_depth
  File "wt_file_manager.py", line 262, in __scan_with_depth
TypeError: '>=' not supported between instances of 'NoneType' and 'int'

2024-07-16 23:14:55,956 - wt_main.py[line:247] - ERROR: 【取证】程序出错：Traceback (most recent call last):
  File "wt_main.py", line 191, in QZ_run
  File "wt_file_manager.py", line 225, in scan_with_depth
  File "wt_file_manager.py", line 262, in __scan_with_depth
TypeError: '>=' not supported between instances of 'NoneType' and 'int'

2024-07-16 23:14:56,024 - wt_main.py[line:247] - ERROR: 【取证】程序出错：Traceback (most recent call last):
  File "wt_main.py", line 191, in QZ_run
  File "wt_file_manager.py", line 225, in scan_with_depth
  File "wt_file_manager.py", line 262, in __scan_with_depth
TypeError: '>=' not supported between instances of 'NoneType' and 'int'

2024-07-16 23:14:56,089 - wt_main.py[line:247] - ERROR: 【取证】程序出错：Traceback (most recent call last):
  File "wt_main.py", line 191, in QZ_run
  File "wt_file_manager.py", line 225, in scan_with_depth
  File "wt_file_manager.py", line 262, in __scan_with_depth
TypeError: '>=' not supported between instances of 'NoneType' and 'int'

2024-07-16 23:14:56,155 - wt_main.py[line:247] - ERROR: 【取证】程序出错：Traceback (most recent call last):
  File "wt_main.py", line 191, in QZ_run
  File "wt_file_manager.py", line 225, in scan_with_depth
  File "wt_file_manager.py", line 262, in __scan_with_depth
TypeError: '>=' not supported between instances of 'NoneType' and 'int'

2024-07-16 23:14:56,221 - wt_main.py[line:247] - ERROR: 【取证】程序出错：Traceback (most recent call last):
  File "wt_main.py", line 191, in QZ_run
  File "wt_file_manager.py", line 225, in scan_with_depth
  File "wt_file_manager.py", line 262, in __scan_with_depth
TypeError: '>=' not supported between instances of 'NoneType' and 'int'

2024-07-16 23:14:56,295 - wt_main.py[line:247] - ERROR: 【取证】程序出错：Traceback (most recent call last):
  File "wt_main.py", line 191, in QZ_run
  File "wt_file_manager.py", line 225, in scan_with_depth
  File "wt_file_manager.py", line 262, in __scan_with_depth
TypeError: '>=' not supported between instances of 'NoneType' and 'int'

2024-07-16 23:14:56,362 - wt_main.py[line:247] - ERROR: 【取证】程序出错：Traceback (most recent call last):
  File "wt_main.py", line 191, in QZ_run
  File "wt_file_manager.py", line 225, in scan_with_depth
  File "wt_file_manager.py", line 262, in __scan_with_depth
TypeError: '>=' not supported between instances of 'NoneType' and 'int'

2024-07-16 23:14:56,431 - wt_main.py[line:247] - ERROR: 【取证】程序出错：Traceback (most recent call last):
  File "wt_main.py", line 191, in QZ_run
  File "wt_file_manager.py", line 225, in scan_with_depth
  File "wt_file_manager.py", line 262, in __scan_with_depth
TypeError: '>=' not supported between instances of 'NoneType' and 'int'

2024-07-16 23:14:56,499 - wt_main.py[line:247] - ERROR: 【取证】程序出错：Traceback (most recent call last):
  File "wt_main.py", line 191, in QZ_run
  File "wt_file_manager.py", line 225, in scan_with_depth
  File "wt_file_manager.py", line 262, in __scan_with_depth
TypeError: '>=' not supported between instances of 'NoneType' and 'int'

2024-07-16 23:14:56,565 - wt_main.py[line:247] - ERROR: 【取证】程序出错：Traceback (most recent call last):
  File "wt_main.py", line 191, in QZ_run
  File "wt_file_manager.py", line 225, in scan_with_depth
  File "wt_file_manager.py", line 262, in __scan_with_depth
TypeError: '>=' not supported between instances of 'NoneType' and 'int'

2024-07-16 23:14:56,630 - wt_main.py[line:247] - ERROR: 【取证】程序出错：Traceback (most recent call last):
  File "wt_main.py", line 191, in QZ_run
  File "wt_file_manager.py", line 225, in scan_with_depth
  File "wt_file_manager.py", line 262, in __scan_with_depth
TypeError: '>=' not supported between instances of 'NoneType' and 'int'

2024-07-16 23:14:56,695 - wt_main.py[line:247] - ERROR: 【取证】程序出错：Traceback (most recent call last):
  File "wt_main.py", line 191, in QZ_run
  File "wt_file_manager.py", line 225, in scan_with_depth
  File "wt_file_manager.py", line 262, in __scan_with_depth
TypeError: '>=' not supported between instances of 'NoneType' and 'int'

2024-07-16 23:14:56,759 - wt_main.py[line:247] - ERROR: 【取证】程序出错：Traceback (most recent call last):
  File "wt_main.py", line 191, in QZ_run
  File "wt_file_manager.py", line 225, in scan_with_depth
  File "wt_file_manager.py", line 262, in __scan_with_depth
TypeError: '>=' not supported between instances of 'NoneType' and 'int'

2024-07-16 23:14:56,827 - wt_main.py[line:247] - ERROR: 【取证】程序出错：Traceback (most recent call last):
  File "wt_main.py", line 191, in QZ_run
  File "wt_file_manager.py", line 225, in scan_with_depth
  File "wt_file_manager.py", line 262, in __scan_with_depth
TypeError: '>=' not supported between instances of 'NoneType' and 'int'

2024-07-16 23:14:56,890 - wt_main.py[line:247] - ERROR: 【取证】程序出错：Traceback (most recent call last):
  File "wt_main.py", line 191, in QZ_run
  File "wt_file_manager.py", line 225, in scan_with_depth
  File "wt_file_manager.py", line 262, in __scan_with_depth
TypeError: '>=' not supported between instances of 'NoneType' and 'int'

2024-07-16 23:14:56,956 - wt_main.py[line:247] - ERROR: 【取证】程序出错：Traceback (most recent call last):
  File "wt_main.py", line 191, in QZ_run
  File "wt_file_manager.py", line 225, in scan_with_depth
  File "wt_file_manager.py", line 262, in __scan_with_depth
TypeError: '>=' not supported between instances of 'NoneType' and 'int'

2024-07-16 23:14:57,022 - wt_main.py[line:247] - ERROR: 【取证】程序出错：Traceback (most recent call last):
  File "wt_main.py", line 191, in QZ_run
  File "wt_file_manager.py", line 225, in scan_with_depth
  File "wt_file_manager.py", line 262, in __scan_with_depth
TypeError: '>=' not supported between instances of 'NoneType' and 'int'

2024-07-16 23:14:57,088 - wt_main.py[line:247] - ERROR: 【取证】程序出错：Traceback (most recent call last):
  File "wt_main.py", line 191, in QZ_run
  File "wt_file_manager.py", line 225, in scan_with_depth
  File "wt_file_manager.py", line 262, in __scan_with_depth
TypeError: '>=' not supported between instances of 'NoneType' and 'int'

2024-07-16 23:14:57,153 - wt_main.py[line:247] - ERROR: 【取证】程序出错：Traceback (most recent call last):
  File "wt_main.py", line 191, in QZ_run
  File "wt_file_manager.py", line 225, in scan_with_depth
  File "wt_file_manager.py", line 262, in __scan_with_depth
TypeError: '>=' not supported between instances of 'NoneType' and 'int'

2024-07-16 23:14:57,219 - wt_main.py[line:247] - ERROR: 【取证】程序出错：Traceback (most recent call last):
  File "wt_main.py", line 191, in QZ_run
  File "wt_file_manager.py", line 225, in scan_with_depth
  File "wt_file_manager.py", line 262, in __scan_with_depth
TypeError: '>=' not supported between instances of 'NoneType' and 'int'

2024-07-16 23:14:57,285 - wt_main.py[line:247] - ERROR: 【取证】程序出错：Traceback (most recent call last):
  File "wt_main.py", line 191, in QZ_run
  File "wt_file_manager.py", line 225, in scan_with_depth
  File "wt_file_manager.py", line 262, in __scan_with_depth
TypeError: '>=' not supported between instances of 'NoneType' and 'int'

2024-07-16 23:14:57,352 - wt_main.py[line:247] - ERROR: 【取证】程序出错：Traceback (most recent call last):
  File "wt_main.py", line 191, in QZ_run
  File "wt_file_manager.py", line 225, in scan_with_depth
  File "wt_file_manager.py", line 262, in __scan_with_depth
TypeError: '>=' not supported between instances of 'NoneType' and 'int'

2024-07-16 23:14:57,417 - wt_main.py[line:247] - ERROR: 【取证】程序出错：Traceback (most recent call last):
  File "wt_main.py", line 191, in QZ_run
  File "wt_file_manager.py", line 225, in scan_with_depth
  File "wt_file_manager.py", line 262, in __scan_with_depth
TypeError: '>=' not supported between instances of 'NoneType' and 'int'

2024-07-16 23:14:57,485 - wt_main.py[line:247] - ERROR: 【取证】程序出错：Traceback (most recent call last):
  File "wt_main.py", line 191, in QZ_run
  File "wt_file_manager.py", line 225, in scan_with_depth
  File "wt_file_manager.py", line 262, in __scan_with_depth
TypeError: '>=' not supported between instances of 'NoneType' and 'int'

2024-07-16 23:14:57,556 - wt_main.py[line:247] - ERROR: 【取证】程序出错：Traceback (most recent call last):
  File "wt_main.py", line 191, in QZ_run
  File "wt_file_manager.py", line 225, in scan_with_depth
  File "wt_file_manager.py", line 262, in __scan_with_depth
TypeError: '>=' not supported between instances of 'NoneType' and 'int'

2024-07-16 23:14:57,632 - wt_main.py[line:247] - ERROR: 【取证】程序出错：Traceback (most recent call last):
  File "wt_main.py", line 191, in QZ_run
  File "wt_file_manager.py", line 225, in scan_with_depth
  File "wt_file_manager.py", line 262, in __scan_with_depth
TypeError: '>=' not supported between instances of 'NoneType' and 'int'

2024-07-16 23:14:57,704 - wt_main.py[line:247] - ERROR: 【取证】程序出错：Traceback (most recent call last):
  File "wt_main.py", line 191, in QZ_run
  File "wt_file_manager.py", line 225, in scan_with_depth
  File "wt_file_manager.py", line 262, in __scan_with_depth
TypeError: '>=' not supported between instances of 'NoneType' and 'int'

2024-07-16 23:14:57,783 - wt_main.py[line:247] - ERROR: 【取证】程序出错：Traceback (most recent call last):
  File "wt_main.py", line 191, in QZ_run
  File "wt_file_manager.py", line 225, in scan_with_depth
  File "wt_file_manager.py", line 262, in __scan_with_depth
TypeError: '>=' not supported between instances of 'NoneType' and 'int'

2024-07-16 23:14:57,860 - wt_main.py[line:247] - ERROR: 【取证】程序出错：Traceback (most recent call last):
  File "wt_main.py", line 191, in QZ_run
  File "wt_file_manager.py", line 225, in scan_with_depth
  File "wt_file_manager.py", line 262, in __scan_with_depth
TypeError: '>=' not supported between instances of 'NoneType' and 'int'

2024-07-16 23:14:57,930 - wt_main.py[line:247] - ERROR: 【取证】程序出错：Traceback (most recent call last):
  File "wt_main.py", line 191, in QZ_run
  File "wt_file_manager.py", line 225, in scan_with_depth
  File "wt_file_manager.py", line 262, in __scan_with_depth
TypeError: '>=' not supported between instances of 'NoneType' and 'int'

2024-07-16 23:14:57,995 - wt_main.py[line:247] - ERROR: 【取证】程序出错：Traceback (most recent call last):
  File "wt_main.py", line 191, in QZ_run
  File "wt_file_manager.py", line 225, in scan_with_depth
  File "wt_file_manager.py", line 262, in __scan_with_depth
TypeError: '>=' not supported between instances of 'NoneType' and 'int'

2024-07-16 23:14:58,060 - wt_main.py[line:247] - ERROR: 【取证】程序出错：Traceback (most recent call last):
  File "wt_main.py", line 191, in QZ_run
  File "wt_file_manager.py", line 225, in scan_with_depth
  File "wt_file_manager.py", line 262, in __scan_with_depth
TypeError: '>=' not supported between instances of 'NoneType' and 'int'

2024-07-16 23:14:58,125 - wt_main.py[line:247] - ERROR: 【取证】程序出错：Traceback (most recent call last):
  File "wt_main.py", line 191, in QZ_run
  File "wt_file_manager.py", line 225, in scan_with_depth
  File "wt_file_manager.py", line 262, in __scan_with_depth
TypeError: '>=' not supported between instances of 'NoneType' and 'int'

2024-07-16 23:14:58,191 - wt_main.py[line:247] - ERROR: 【取证】程序出错：Traceback (most recent call last):
  File "wt_main.py", line 191, in QZ_run
  File "wt_file_manager.py", line 225, in scan_with_depth
  File "wt_file_manager.py", line 262, in __scan_with_depth
TypeError: '>=' not supported between instances of 'NoneType' and 'int'

2024-07-16 23:14:58,255 - wt_main.py[line:247] - ERROR: 【取证】程序出错：Traceback (most recent call last):
  File "wt_main.py", line 191, in QZ_run
  File "wt_file_manager.py", line 225, in scan_with_depth
  File "wt_file_manager.py", line 262, in __scan_with_depth
TypeError: '>=' not supported between instances of 'NoneType' and 'int'

2024-07-16 23:14:58,320 - wt_main.py[line:247] - ERROR: 【取证】程序出错：Traceback (most recent call last):
  File "wt_main.py", line 191, in QZ_run
  File "wt_file_manager.py", line 225, in scan_with_depth
  File "wt_file_manager.py", line 262, in __scan_with_depth
TypeError: '>=' not supported between instances of 'NoneType' and 'int'

2024-07-16 23:14:58,385 - wt_main.py[line:247] - ERROR: 【取证】程序出错：Traceback (most recent call last):
  File "wt_main.py", line 191, in QZ_run
  File "wt_file_manager.py", line 225, in scan_with_depth
  File "wt_file_manager.py", line 262, in __scan_with_depth
TypeError: '>=' not supported between instances of 'NoneType' and 'int'

2024-07-16 23:14:58,450 - wt_main.py[line:247] - ERROR: 【取证】程序出错：Traceback (most recent call last):
  File "wt_main.py", line 191, in QZ_run
  File "wt_file_manager.py", line 225, in scan_with_depth
  File "wt_file_manager.py", line 262, in __scan_with_depth
TypeError: '>=' not supported between instances of 'NoneType' and 'int'

2024-07-16 23:14:58,514 - wt_main.py[line:247] - ERROR: 【取证】程序出错：Traceback (most recent call last):
  File "wt_main.py", line 191, in QZ_run
  File "wt_file_manager.py", line 225, in scan_with_depth
  File "wt_file_manager.py", line 262, in __scan_with_depth
TypeError: '>=' not supported between instances of 'NoneType' and 'int'

2024-07-16 23:14:58,579 - wt_main.py[line:247] - ERROR: 【取证】程序出错：Traceback (most recent call last):
  File "wt_main.py", line 191, in QZ_run
  File "wt_file_manager.py", line 225, in scan_with_depth
  File "wt_file_manager.py", line 262, in __scan_with_depth
TypeError: '>=' not supported between instances of 'NoneType' and 'int'

2024-07-16 23:14:58,645 - wt_main.py[line:247] - ERROR: 【取证】程序出错：Traceback (most recent call last):
  File "wt_main.py", line 191, in QZ_run
  File "wt_file_manager.py", line 225, in scan_with_depth
  File "wt_file_manager.py", line 262, in __scan_with_depth
TypeError: '>=' not supported between instances of 'NoneType' and 'int'

2024-07-16 23:14:58,710 - wt_main.py[line:247] - ERROR: 【取证】程序出错：Traceback (most recent call last):
  File "wt_main.py", line 191, in QZ_run
  File "wt_file_manager.py", line 225, in scan_with_depth
  File "wt_file_manager.py", line 262, in __scan_with_depth
TypeError: '>=' not supported between instances of 'NoneType' and 'int'

2024-07-16 23:14:58,780 - wt_main.py[line:247] - ERROR: 【取证】程序出错：Traceback (most recent call last):
  File "wt_main.py", line 191, in QZ_run
  File "wt_file_manager.py", line 225, in scan_with_depth
  File "wt_file_manager.py", line 262, in __scan_with_depth
TypeError: '>=' not supported between instances of 'NoneType' and 'int'

2024-07-16 23:15:24,398 - wt_main.py[line:179] - INFO: 开始扫描取证文件夹：D:\历史项目管理\AutoScanning交通扫描软件\AutoScanning\dist\新建文件夹
2024-07-16 23:17:35,393 - wt_main.py[line:179] - INFO: 开始扫描取证文件夹：D:\历史项目管理\AutoScanning交通扫描软件\AutoScanning\dist\新建文件夹
2024-07-16 23:17:39,819 - wt_main.py[line:179] - INFO: 开始扫描取证文件夹：D:\历史项目管理\AutoScanning交通扫描软件\AutoScanning\dist\新建文件夹
2024-07-16 23:17:39,952 - wt_main.py[line:179] - INFO: 开始扫描取证文件夹：D:\历史项目管理\AutoScanning交通扫描软件\AutoScanning\dist\新建文件夹
2024-07-16 23:17:40,087 - wt_main.py[line:179] - INFO: 开始扫描取证文件夹：D:\历史项目管理\AutoScanning交通扫描软件\AutoScanning\dist\新建文件夹
2024-07-16 23:17:40,231 - wt_main.py[line:179] - INFO: 开始扫描取证文件夹：D:\历史项目管理\AutoScanning交通扫描软件\AutoScanning\dist\新建文件夹
2024-07-16 23:17:40,367 - wt_main.py[line:179] - INFO: 开始扫描取证文件夹：D:\历史项目管理\AutoScanning交通扫描软件\AutoScanning\dist\新建文件夹
2024-07-16 23:17:40,512 - wt_main.py[line:179] - INFO: 开始扫描取证文件夹：D:\历史项目管理\AutoScanning交通扫描软件\AutoScanning\dist\新建文件夹
2024-07-16 23:17:40,657 - wt_main.py[line:179] - INFO: 开始扫描取证文件夹：D:\历史项目管理\AutoScanning交通扫描软件\AutoScanning\dist\新建文件夹
2024-07-16 23:17:40,794 - wt_main.py[line:179] - INFO: 开始扫描取证文件夹：D:\历史项目管理\AutoScanning交通扫描软件\AutoScanning\dist\新建文件夹
2024-07-16 23:17:41,580 - wt_main.py[line:179] - INFO: 开始扫描取证文件夹：D:\历史项目管理\AutoScanning交通扫描软件\AutoScanning\dist\新建文件夹
2024-07-16 23:40:24,143 - wt_main.py[line:181] - INFO: 开始扫描取证文件夹：D:\历史项目管理\AutoScanning交通扫描软件\AutoScanning\dist\新建文件夹
